<?xml version="1.0"?>
<robot name="fridge_bottom">
  <link name="cabinet">
    <visual>
      <geometry><box size="0.2 0.3 0.366"/></geometry>
      <material name="gray"><color rgba="0.5 0.5 0.5 1"/></material>
      <origin xyz="0 0 0.183"/>
    </visual>
    <collision>
      <geometry><box size="0.2 0.3 0.366"/></geometry>
      <origin xyz="0 0 0.183"/>
    </collision>
    <inertial>
      <mass value="3.0"/><inertia ixx="0.1" ixy="0" ixz="0" iyy="0.1" iyz="0" izz="0.1"/>
    </inertial>
  </link>

  <joint name="fridge_hinge" type="revolute">
    <axis xyz="0 0 1"/>
    <limit effort="100.0" lower="-1.57" upper="0." velocity="40"/>
    <parent link="cabinet"/>
    <child link="fridge_door"/>
    <origin xyz="0.1 -0.15 0.016"/>
  </joint>

  <link name="fridge_door">
    <visual>
      <geometry><box size="0.007 0.3 0.334"/></geometry>
      <material name="white"><color rgba="1 1 1 1"/></material>
      <origin xyz="0.0035 0.15 0.167"/>
    </visual>
    <collision>
      <geometry><box size="0.007 0.3 0.334"/></geometry>
      <origin xyz="0.0035 0.15 0.167"/>
    </collision>
  </link>

  <joint name="handle_joint" type="fixed">
    <parent link="fridge_door"/>
    <child link="door_handle"/>
    <origin xyz="0.015 0.27 0.167"/>
  </joint>

  <link name="door_handle">
    <contact>
       <lateral_friction value="2.0"/>
       <spinning_friction value="0.01"/>
    </contact>
    <visual>
      <geometry><box size="0.015 0.007 0.1"/></geometry>
      <material name="red"><color rgba="1 0 0 1"/></material>
    </visual>
    <collision><geometry><box size="0.015 0.007 0.1"/></geometry></collision>
  </link>
</robot>